Workbook
Name __FDS_HYPERLINK_TOGGLE_STATE__: "ON"
Name __FDS_UNIQUE_RANGE_ID_GENERATOR_COUNTER: 28
Name __FDS_USED_FOR_REUSING_RANGE_IDS_RECYCLE: {16,16,16,16,16,16,16,16,16,16,16}
Name __FDS_USED_FOR_REUSING_RANGE_IDS_RECYCLE: {16,16,16,16,16,16,16,16,16,16,16}
Name __FDS_USED_FOR_REUSING_RANGE_IDS_RECYCLE: {16,16,16,16,16,16,16,16,16,16,16}
Name __FDS_USED_FOR_REUSING_RANGE_IDS_RECYCLE: {16,16,16,16,16,16,16,16,16,16,16}
Name __FDS_USED_FOR_REUSING_RANGE_IDS_RECYCLE: {16,16,16,16,16,16,16,16,16,16,16}
Name __FDS_USED_FOR_REUSING_RANGE_IDS_RECYCLE_1: {16,16,16,16,16,16,16,16,16,16,16}
Name _10a2_: {"Client Name or Project Name"}
Name _11a2_: {"Client Name or Project Name"}
Name _12a2_: {"Client Name or Project Name"}
Name _12a2_: {"Client Name or Project Name"}
Name _12a2_: {"Client Name or Project Name"}
Name _12a2_: {"Client Name or Project Name"}
Name _12a2_: {"Client Name or Project Name"}
Name _12a2__1: {"Client Name or Project Name"}
Name _13a2_: {"Client Name or Project Name"}
Name _14a2_: {"Client Name or Project Name"}
Name _14a2_: {"Client Name or Project Name"}
Name _14a2__1: {"Client Name or Project Name"}
Name _1999E: #REF!
Name _1a1_: {"Client Name or Project Name"}
Name _1a1_: {"Client Name or Project Name"}
Name _1a1_: {"Client Name or Project Name"}
Name _1a1_: {"Client Name or Project Name"}
Name _1a1_: {"Client Name or Project Name"}
Name _1a1__1: {"Client Name or Project Name"}
Name _1Q97A: #REF!
Name _1Q98A: #REF!
Name _1Q99A: #REF!
Name _2000E: #REF!
Name _2001E: #REF!
Name _2002E: #REF!
Name _2003E: #REF!
Name _2004E: #REF!
Name _2005E: #REF!
Name _2006E: #REF!
Name _2007E: #REF!
Name _2008E: #REF!
Name _2a1_: {"Client Name or Project Name"}
Name _2a1_: {"Client Name or Project Name"}
Name _2a1_: {"Client Name or Project Name"}
Name _2a1_: {"Client Name or Project Name"}
Name _2a1_: {"Client Name or Project Name"}
Name _2a1__1: {"Client Name or Project Name"}
Name _2a2_: {"Client Name or Project Name"}
Name _2a2_: {"Client Name or Project Name"}
Name _2a2_: {"Client Name or Project Name"}
Name _2a2_: {"Client Name or Project Name"}
Name _2a2__1: {"Client Name or Project Name"}
Name _2Q97A: #REF!
Name _2Q98A: #REF!
Name _2Q99A: #REF!
Name _3a1_: {"Client Name or Project Name"}
Name _3Q97A: #REF!
Name _3Q98A: #REF!
Name _4a1_: {"Client Name or Project Name"}
Name _4a1_: {"Client Name or Project Name"}
Name _4a1_: {"Client Name or Project Name"}
Name _4a1_: {"Client Name or Project Name"}

Sheet Header(C)
C5: 中国建筑国际(03311.HK)
C6: 更新日期： | D6: =TODAY() -> 46120
C11: 陈彦，CFA | F11: 任嘉禹
C12: (00852)94723508 | F12: 18801066373
C13: yan3.chen@cicc.com.cn | F13: jiayu.ren@cicc.com.cn
C15: 资料来源：万得，彭博，中金公司研究部
A17: 法律声明 一般声明 本资料由中国国际金融股份有限公司（已具备中国证监会批复的证券投资咨询业务资格）制作。本资料中的信息均来源于我们认为可靠的已公开资料，但中国国际金融股份有限公司及其关联机构（以下统称“中金公司”）对这些信息的准确性及完整性不作任何保证。本资料中的信息、意见等均仅供投资者参考之用，不构成对买卖任何证券或其他金融工具的出价或征价或提供任何投资决策建议的服务。该等信息、意见并未考虑到获取本资料人员的具体投资目的、财务状况以及特定需求，在任何时候均不构成对任何人的个人推荐或投资操作性建议。投资者应当对本资料中的信息和意见进行独立评估，自主审慎做出决策并自行承担风险。投资者在依据本资料涉及的内容进行任何决策前，应同时考量各自的投资目的、财务状况和特定需求，并就相关决策咨询专业顾问的意见对依据或者使用本资料所造成的一切后果，中金公司及/或其关联人员均不承担任何责任。 本资料所载的意见、评估及预测仅为本资料出具日的观点和判断。该等意见、评估及预测无需通知即可随时更改。在不同时期，中金公司可能会发出与本资料所载意见、评估及预测不一致的研究资料。 本资料署名分析师可能会不时与中金公司的客户、销售交易人员、其他业务人员或在本资料中针对可能对本资料所涉及的标的证券或其他金融工具的市场价格产生短期影响的催化剂或事件进行交易策略的讨论。这种短期影响的分析可能与分析师已发布的关于相关证券或其他金融工具的目标价、评级、估值、预测等观点相反或不一致，相关的交易策略不同于且也不影响分析师关于其所研究标的证券或其他金融工具的基本面评级。 中金公司的销售人员、交易人员以及其他专业人士可能会依据不同假设和标准、采用不同的分析方法而口头或书面发表与本资料意见及建议不一致的市场评论和/或交易观点。中金公司没有将此意见及建议向资料所有接收者进行更新的义务。中金公司的资产管理部门、自营部门以及其他投资业务部门可能独立做出与本资料中的意见不一致的投资决策。 除非另行说明，本资料中所引用的关于业绩的数据代表过往表现。过往的业绩表现亦不应作为日后回报的预示。我们不承诺也不保证，任何所预示的回报会得以实现。分析中所做的预测可能是基于相应的假设。任何假设的变化可能会显著地影响所预测的回报。 本资料提供给某接收人是基于该接收人被认为有能力独立评估投资风险并就投资决策能行使独立判断。投资的独立判断是指，投资决策是投资者自身基于对潜在投资的目标、需求、机会、风险、市场因素及其他投资考虑而独立做出的。 本资料由受香港证券和期货委员会监管的中国国际金融香港证券有限公司（“中金香港”）于香港提供。香港的投资者若有任何关于中金公司研究资料的问题请直接联系中金香港的销售交易代表。 本资料由受新加坡金融管理局监管的中国国际金融（新加坡）有限公司 (“中金新加坡”) 于新加坡向符合新加坡《证券期货法》定义下的认可投资者及/或机构投资者提供。提供本资料于此类投资者, 有关财务顾问将无需根据新加坡之《财务顾问法》第36 条就任何利益及/或其代表就任何证券利益进行披露。有关本资料之任何查询，在新加坡获得本资料的人员可联系中金新加坡销售交易代表。 本资料由受金融服务监管局监管的中国国际金融（英国）有限公司（“中金英国”）于英国提供。本资料有关的投资和服务仅向符合《2000年金融服务和市场法2005年（金融推介）令》第19（5）条、 38条、 47条以及 49条规定的人士提供。本资料并未打算提供给零售客户使用。在其他欧洲经济区国家，本资料向被其本国认定为专业投资者（或相当性质）的人士提供。 本资料将依据其他国家或地区的法律法规和监管要求于该国家或地区提供。 特别声明 在法律许可的情况下，中金公司可能与本资料中提及公司正在建立或争取建立业务关系或服务关系。因此，投资者应当考虑到中金公司及/或其相关人员可能存在影响本资料观点客观性的潜在利益冲突。 与本资料所含具体公司相关的披露信息请访https://research.cicc.com/footer/disclosures，亦可参见近期已发布的关于该等公司的具体研究资料。 中金研究基本评级体系说明： 分析师采用相对评级体系，股票评级分为跑赢行业、中性、跑输行业（定义见下文）。 除了股票评级外，中金公司对覆盖行业的未来市场表现提供行业评级观点，行业评级分为超配、标配、低配（定义见下文）。 我们在此提醒您，中金公司对研究覆盖的股票不提供买入、卖出评级。跑赢行业、跑输行业不等同于买入、卖出。投资者应仔细阅读中金公司研究报告中的所有评级定义。请投资者仔细阅读研究报告全文，以获取比较完整的观点与信息，不应仅仅依靠评级来推断结论。在任何情形下，评级（或研究观点）都不应被视为或作为投资建议。投资者买卖证券或其他金融产品的决定应基于自身实际具体情况（比如当前的持仓结构）及其他需要考虑的因素。 股票评级定义：  跑赢行业（OUTPERFORM）：未来6~12个月，分析师预计个股表现超过同期其所属的中金行业指数；  中性（NEUTRAL）：未来6~12个月，分析师预计个股表现与同期其所属的中金行业指数相比持平；  跑输行业（UNDERPERFORM）：未来6~12个月，分析师预计个股表现不及同期其所属的中金行业指数。 行业评级定义：  超配（OVERWEIGHT）：未来6~12个月，分析师预计某行业会跑赢大盘10%以上；  标配（EQUAL-WEIGHT）：未来6~12个月，分析师预计某行业表现与大盘的关系在-10%与10%之间；  低配（UNDERWEIGHT）：未来6~12个月，分析师预计某行业会跑输大盘10%以上。 研究报告评级分布可从https://research.cicc.com/footer/disclosures 获悉。 本报告的版权仅为中金公司所有，未经书面许可任何机构和个人不得以任何形式转发、翻版、复制、刊登、发表或引用。

Sheet Header(E)
C5: China State Construction Int'l(03311.HK)
C6: update as of | D6: ='Header(C)'!D6 -> 46120
C11: Yan CHEN, CFA | F11: Jiayu REN
C12: (00852)94723508 | F12: 18801066373
C13: yan3.chen@cicc.com.cn | F13: jiayu.ren@cicc.com.cn
C15: Source: Wind, Bloomberg, CICC Research
A17: General Disclosures This document has been produced by China International Capital Corporation Hong Kong Securities Limited (CICCHKS). This document is based on information available to the public that we consider reliable, but CICCHKS and its associated company(ies)(collectively, hereinafter “CICC”) do not represent that it is accurate or complete. The information and opinions contained herein are for investors’ reference only and do not take into account the particular investment objectives, financial situation, or needs of any client, and are not an offer to buy or sell or a solicitation of an offer to buy or sell any securities/financial products or to participate in any particular trading strategy. Under no circumstances shall the information contained herein or the opinions expressed herein constitute a personal recommendation to anyone. Investors should make their own independent evaluation of the information contained in this research document, consider their own individual investment objectives, financial situation and particular needs. CICC does not provide tax, accounting, or legal advice to our clients, and all investors are advised to consult with their tax, accounting, or legal advisers regarding any potential investment. Neither CICC nor its related persons shall be liable in any manner whatsoever for any consequences of any reliance thereon or usage thereof. The performance information (including any expression of opinion or forecast) herein reflect the most up-to-date opinions, speculations and forecasts at the time of the document’s production and publication. Such opinions, speculations and forecasts are subject to change and may be amended without any notification. At different periods, CICC may release documents which are inconsistent with the opinions, speculations and forecasts contained herein. The analysts named in this document may have from time to time discussed with our clients, including CICC salespeople, traders, and other professionals, or may discuss in this document, trading strategies that reference catalysts or events that may have a near-term impact on the market price of the equity securities discussed in this document, which impact may be directionally counter to the analysts' published price target expectations for such stocks. Any such trading strategies are distinct from and do not affect the analysts' fundamental equity rating for such stocks as described herein. CICC’s salespeople, traders, and other professionals may provide oral or written market commentary or trading ideas that may be inconsistent with, and reach different conclusions from, the recommendations and opinions presented in this document. Such ideas or recommendations reflect the different assumptions, views and analytical methods of the persons who prepared them, and CICC is under no obligation to ensure that such other trading ideas or recommendations are brought to the attention of any recipient of this document. CICC’s asset management area, proprietary trading desks and other investing businesses may make investment decisions that are inconsistent with the recommendations or opinions expressed in this document. Unless stated otherwise, any performance data quoted represents past performance. Past performance is not an indicator of future performance. No representation or warranty is made that any returns indicated will be achieved. Certain assumptions may have been made in this analysis which has resulted in any returns detailed herein. Changes to the assumptions may have a material impact on any returns detailed. To the extent this material is provided to any recipient, this material is provided solely on the basis that the recipient has the capability to independently evaluate investment risk and is exercising independent judgment in evaluating investment decisions in that its investment decisions will be based on its own independent assessment of the opportunities and risks presented by a potential investment, market factors and other investment considerations. This document is distributed in Hong Kong by CICCHKS, which is regulated by the Securities and Futures Commission. Queries concerning CICC Research from readers in Hong Kong should be directed to our Hong Kong sales representatives. This document is distributed in Singapore only to accredited investors and/or institutional investors, as defined in the Securities and Futures Act, by China International Capital Corporation (Singapore) Pte. Limited (“CICCSG”), which is regulated by the Monetary Authority of Singapore. By virtue of distribution by CICCSG to these categories of investors in Singapore, disclosure under Section 36 of the Financial Adviser Act (which relates to disclosure of a financial adviser’s interest and/or its representative’s interest in securities) is not required. Recipients of this document in Singapore should contact CICCSG in respect of any matter arising from or in connection with this document. This document is not intended for and should not be distributed or passed on, directly or indirectly, to any other person in the jurisdiction of Singapore. This document is distributed in the United Kingdom by China International Capital Corporation (UK) Limited (“CICCUK”), which is authorized and regulated by the Financial Conduct Authority. The investments and services to which this document relates are only available to persons of a kind described in Article 19 (5), 38, 47 and 49 of the Financial Services and Markets Act 2000 (Financial Promotion) Order 2005. This document is not intended for retail clients. In other EEA countries, the document is issued to persons regarded as professional investors (or equivalent) in their home jurisdiction. This document will be made available in other jurisdictions pursuant to the applicable laws and regulations in those particular jurisdictions. Special Disclosures CICC does and seeks to do business with companies covered in CICC Research. As a result, investors should be aware that CICC and/or its associated persons may have a conflict of interest that could affect the objectivity of this document. Disclosures in relation to the Companies contained this document could be found at https://research.cicc.com/footer/disclosures, or in the published latest company-specific research. Guide to the CICC Fundamental Equity Research Rating System: Our analysts use a stock rating framework in which they rate stocks as OUTPERFORM, NEUTRAL or UNDERPERFORM (see definitions below). In addition to the stock rating, we provide industry views which rate the outlook for the industry coverage universe as OVERWEIGHT, EQUAL-WEIGHT or UNDERWEIGHT (see definitions below). CICC does not assign ratings of BUY, HOLD or SELL to the stocks we cover. OUTPERFORM, NEUTRAL or UNDERPERFORM are not the equivalent of BUY, HOLD or SELL. Investors should carefully read the definitions of all ratings used in CICC Research. In addition, since CICC Research contains more complete information concerning the analyst's views, investors should carefully read CICC Research, in its entirety, and not infer the contents from the rating alone. In any case, ratings (or research) should not be used or relied upon as investment advice. An investor's decision to buy or sell a stock should depend on individual circumstances (such as the investor's existing holdings) and other considerations. Explanation of Stock Ratings:  OUTPERFORM: Our analysts expect the stock’s return to exceed the return of the corresponding CICC sector index over the next 6~12 months;  NEUTRAL: Our analysts expect the stock’s return to be in line with the return of the corresponding CICC sector index over the next 6~12 months;  UNDERPERFORM: Our analysts expect the stock’s return to be below the return of the corresponding CICC sector index over the next 6~12 months. Explanation of Industry Ratings:  OVERWEIGHT: Our analysts expect the sector to outperform the market by 10% or more over the next 6~12 months;  EQUAL-WEIGHT: Our analysts expect the sector to end up between 10% below and 10% above the market over the next 6~12 months;  UNDERWEIGHT: Our analysts expect the sector to fall behind the market by 10% or more over the next 6~12 months. Distribution of ratings is available at https://research.cicc.com/footer/disclosures. Copyright of this document belongs to CICC. Any form of unauthorized distribution, reproduction, publication, release or quotation is prohibited without CICC’s written permission.

Sheet Header(E)-US
C5: China State Construction Int'l(03311.HK)
C6: update as of | D6: ='Header(C)'!D6 -> 46120
C11: Yan CHEN, CFA | F11: Jiayu REN
C12: (00852)94723508 | F12: 18801066373
C13: yan3.chen@cicc.com.cn | F13: jiayu.ren@cicc.com.cn
C15: Source: Wind, Bloomberg, CICC Research
A17: General Disclosures This document has been produced by China International Capital Corporation Hong Kong Securities Limited (CICCHKS). This document is based on information available to the public that we consider reliable, but CICCHKS and its associated company(ies)(collectively, hereinafter “CICC”) do not represent that it is accurate or complete. The information and opinions contained herein are for investors’ reference only and do not take into account the particular investment objectives, financial situation, or needs of any client, and are not an offer to buy or sell or a solicitation of an offer to buy or sell any securities/ financial products or to participate in any particular trading strategy. Under no circumstances shall the information contained herein or the opinions expressed herein constitute a personal recommendation to anyone. Investors should make their own independent evaluation of the information contained in this research document, consider their own individual investment objectives, financial situation and particular needs. CICC does not provide tax, accounting, or legal advice to our clients, and all investors are advised to consult with their tax, accounting, or legal advisers regarding any potential investment. Neither CICC nor its related persons shall be liable in any manner whatsoever for any consequences of any reliance thereon or usage thereof. The performance information (including any expression of opinion or forecast) herein reflect the most up-to-date opinions, speculations and forecasts at the time of the document’s production and publication. Such opinions, speculations and forecasts are subject to change and may be amended without any notification. At different periods, CICC may release documents which are inconsistent with the opinions, speculations and forecasts contained herein. The analysts named in this document may have from time to time discussed with our clients, including CICC salespeople, traders, and other professionals, or may discuss in this document, trading strategies that reference catalysts or events that may have a near-term impact on the market price of the equity securities discussed in this document, which impact may be directionally counter to the analysts' published price target expectations for such stocks. Any such trading strategies are distinct from and do not affect the analysts' fundamental equity rating for such stocks as described herein. CICC’s salespeople, traders, and other professionals may provide oral or written market commentary or trading ideas that may be inconsistent with, and reach different conclusions from, the recommendations and opinions presented in this document. Such ideas or recommendations reflect the different assumptions, views and analytical methods of the persons who prepared them, and CICC is under no obligation to ensure that such other trading ideas or recommendations are brought to the attention of any recipient of this document. CICC’s asset management area, proprietary trading desks and other investing businesses may make investment decisions that are inconsistent with the recommendations or opinions expressed in this document. Unless stated otherwise, any performance data quoted represents past performance. Past performance is not an indicator of future performance. No representation or warranty is made that any returns indicated will be achieved. Certain assumptions may have been made in this analysis which has resulted in any returns detailed herein. Changes to the assumptions may have a material impact on any returns detailed. To the extent this material is provided to any recipient, this material is provided solely on the basis that the recipient has the capability to independently evaluate investment risk and is exercising independent judgment in evaluating investment decisions in that its investment decisions will be based on its own independent assessment of the opportunities and risks presented by a potential investment, market factors and other investment considerations. This document is distributed in Hong Kong by CICCHKS, which is regulated by the Securities and Futures Commission. Queries concerning CICC Research from readers in Hong Kong should be directed to our Hong Kong sales representatives. This document is distributed in Singapore only to accredited investors and/or institutional investors, as defined in the Securities and Futures Act, by China International Capital Corporation (Singapore) Pte. Limited (“CICCSG”), which is regulated by the Monetary Authority of Singapore. By virtue of distribution by CICCSG to these categories of investors in Singapore, disclosure under Section 36 of the Financial Adviser Act (which relates to disclosure of a financial adviser’s interest and/or its representative’s interest in securities) is not required. Recipients of this document in Singapore should contact CICCSG in respect of any matter arising from or in connection with this document. This document is not intended for and should not be distributed or passed on, directly or indirectly, to any other person in the jurisdiction of Singapore. This document is distributed in the United Kingdom by China International Capital Corporation (UK) Limited (“CICCUK”), which is authorized and regulated by the Financial Conduct Authority. The investments and services to which this document relates are only available to persons of a kind described in Article 19 (5), 38, 47 and 49 of the Financial Services and Markets Act 2000 (Financial Promotion) Order 2005. This document is not intended for retail clients. In other EEA countries, the document is issued to persons regarded as professional investors (or equivalent) in their home jurisdiction. This document will be made available in other jurisdictions pursuant to the applicable laws and regulations in those particular jurisdictions. Special Disclosures CICC does and seeks to do business with companies covered in CICC Research. As a result, investors should be aware that CICC and/or its associated persons may have a conflict of interest that could affect the objectivity of this document. Disclosures in relation to the Companies contained this document could be found at https://research.cicc.com/footer/disclosures, or in the published latest company-specific research. Guide to the CICC Fundamental Equity Research Rating System: Our analysts use a stock rating framework in which they rate stocks as OUTPERFORM, NEUTRAL or UNDERPERFORM (see definitions below). In addition to the stock rating, we provide industry views which rate the outlook for the industry coverage universe as OVERWEIGHT, EQUAL-WEIGHT or UNDERWEIGHT (see definitions below). CICC does not assign ratings of BUY, HOLD or SELL to the stocks we cover. OUTPERFORM, NEUTRAL or UNDERPERFORM are not the equivalent of BUY, HOLD or SELL. Investors should carefully read the definitions of all ratings used in CICC Research. In addition, since CICC Research contains more complete information concerning the analyst's views, investors should carefully read CICC Research, in its entirety, and not infer the contents from the rating alone. In any case, ratings (or research) should not be used or relied upon as investment advice. An investor's decision to buy or sell a stock should depend on individual circumstances (such as the investor's existing holdings) and other considerations. Explanation of Stock Ratings:  OUTPERFORM: Our analysts expect the stock’s return to exceed the return of the corresponding CICC sector index over the next 6~12 months;  NEUTRAL: Our analysts expect the stock’s return to be in line with the return of the corresponding CICC sector index over the next 6~12 months;  UNDERPERFORM: Our analysts expect the stock’s return to be below the return of the corresponding CICC sector index over the next 6~12 months. Explanation of Industry Ratings:  OVERWEIGHT: Our analysts expect the sector to outperform the market by 10% or more over the next 6~12 months;  EQUAL-WEIGHT: Our analysts expect the sector to end up between 10% below and 10% above the market over the next 6~12 months;  UNDERWEIGHT: Our analysts expect the sector to fall behind the market by 10% or more over the next 6~12 months. Distribution of ratings is available at https://research.cicc.com/footer/disclosures. Copyright of this document belongs to CICC. Any form of unauthorized distribution, reproduction, publication, release or quotation is prohibited without CICC’s written permission. US Regulatory Disclosures Analyst Certification The analysts who prepared the research document contained herein hereby certify pursuant to Regulation AC of the U.S. Securities and Exchange Commission (the "SEC") that: (i) the views expressed in this research document accurately reflect my personal views about the subject securities and issuers; and (ii) no part of my compensation was, is, or will be, directly or indirectly, related to the specific recommendations or views expressed in this research document. Foreign Broker-Dealer Disclosure This research document was prepared by China International Capital Corporation Limited and China International Capital Corporation Hong Kong Securities Limited (hereinafter "CICC"). CICC is not a registered broker-dealer in the United States and, therefore, is not subject to U.S. rules regarding the preparation of research documents and the independence of research analysts. This research document is provided for distribution to “major U.S. institutional investors” in reliance on the exemption from registration provided by Rule 15a-6 of the U.S. Securities Exchange Act of 1934, as amended (the “Exchange Act”). Any U.S. recipient of this research document wishing to effect any transaction to buy or sell securities or related financial instruments based on the information provided in this research document should do so only through CICC US Securities, Inc. (hereinafter "CICC US"), a registered broker-dealer in the United States. Under no circumstances should any recipient of this research document effect any transaction to buy or sell securities or related financial instruments through CICC. CICC US accepts responsibility for the contents of this research document, subject to the terms set out below, to the extent that it is delivered to a U.S. person other than a major U.S. institutional investor. The analyst whose name appears in this research document is not registered or qualified as a research analyst with the Financial Industry Regulatory Authority (“FINRA”) and may not be an associated person of CICC US and, therefore, may not be subject to applicable restrictions under FINRA Rules on communications with a subject company, public appearances and trading securities held by a research analyst account.

Sheet RAWS
A1: @STOCK_CNAME | B1: 证券简称 | C1: Company Name | D1: China State Construction | BG1: 北京市 | CA1: 推荐 | CB1: FY | CC1: 千万 | CD1: 1995 | CF1: Version2.0 | CG1: 1 | CH1: 上调至 | CI1: Upgrade to | CJ1: 1 | CK1: 推荐 | CL1: BUY
A2: @STOCK_CODE | B2: 证券代码 | C2: Ticker | D2: 3311 | BG2: 上海市 | CA2: 审慎推荐 | CB2: 1Q | CC2: 百万 | CD2: 1996 | CG2: 2 | CH2: 下调至 | CI2: Downgrade to | CJ2: 3 | CK2: 中性 | CL2: HOLD
A3: @INSTTYPE | B3: 模板类型 | C3: Instrument Type | D3: HKINDU | BG3: 广东省 | CA3: 中性 | CB3: 1H | CC3: 万 | CD3: 1997 | CG3: 3 | CH3: 维持 | CI3: Maintain | CJ3: 5 | CK3: 回避 | CL3: SELL
A4: @REC_DIRECTION | B4: 评级方向 | C4: Direction | D4: Maintain | BG4: 天津市 | CA4: 回避 | CB4: 3Q | CC4: 千 | CD4: 1998 | CG4: 4 | CH4: 首次覆盖 | CI4: Initiate with | CJ4: 6 | CK4: 无评级 | CL4: Not rated
A5: @REC | B5: 投资评级 | C5: Recommendation | D5: OUTPERFORM | BG5: 重庆市 | CA5: 长期 | CD5: 1999 | CG5: 5 | CH5: 再次覆盖 | CI5: Resume at
A6: @TARGET | B6: 目标价格 | C6: Share Price Target | D6: 11.63 | BG6: 江苏省 | CA6: 短期 | CD6: 2000
A7: @COMPROFILE_CN | B7: 公司概述 - 中文 | C7: Company Desc - Chinese | D7: 中建国际是中国建筑(601668.SH)旗下子公司，2005年于联交所主板上市。公司经营范围包括房屋工程如公营房屋、私人住宅楼宇、商业、工业、医疗机械、教育文化设施、酒店、公共建设(机场等)；土木工程如土地平整、公路、桥梁、填海、隧道等；以及机电工程等周边业务。目前已打造成港澳、内地及海外(远东环球830.HK)三大区域平台。 | BG7: 浙江省 | CA7: 减持 | CD7: 2001
A8: @COMPROFILE_EN | B8: 公司概述 - 英文 | C8: Company Desc - English | D8: China State Construction International (CSCI), a subsidiary of CSCEC (601668.SH), was listed on the main board of the Hong Kong Stock Exchange in 2005. The company has built three regional business platforms: mainland China, Hong Kong-Macau and overseas. In Hong Kong and Macau, it is one of the largest housing and infrastructure construction contractors, while in mainland China, it focuses on investing in infrastructure and affordable housing (BT). Its overseas platform is operated by Far East (830.HK), an affiliate whose main business is curtain walls. | BG8: 四川省 | CA8: 无评级 | CD8: 2002
A9: @FINA_YEAR | B9: 报表年份 | C9: Reporting Year | K9: 2010 | L9: 2011 | M9: 2012 | N9: 2013 | O9: 2014 | P9: 2015 | Q9: 2016 | R9: 2017 | S9: 2018 | T9: 2019 | U9: 2020 | V9: 2021 | W9: 2022 | X9: 2023 | Y9: 2024 | Z9: 2025 | AA9: 2026 | AB9: 2027 | BG9: 海南省 | CD9: 2003
A10: @FINA_PERIOD | B10: 报表周期 | C10: Reporting Period | K10: FY | L10: FY | M10: FY | N10: FY | O10: FY | P10: FY | Q10: FY | R10: FY | S10: FY | T10: FY | U10: FY | V10: FY | W10: FY | X10: FY | Y10: FY | Z10: FY | AA10: FY | AB10: FY | BG10: 福建省 | CD10: 2004
A11: @ACCOUNTS_STATUS | B11: 报表状态 | C11: Accounts Status | K11: A | L11: A | M11: A | N11: A | O11: A | P11: A | Q11: A | R11: A | S11: A | T11: A | U11: A | V11: A | W11: A | X11: A | Y11: A | Z11: A | AA11: E | AB11: E | BG11: 山东省 | CA11: Buy | CD11: 2005
A12: @MULTIPLIER | B12: 报表单位 | C12: Unit | K12: 百万 | L12: 百万 | M12: 百万 | N12: 百万 | O12: 百万 | P12: 百万 | Q12: 百万 | R12: 百万 | S12: 百万 | T12: 百万 | U12: 百万 | V12: 百万 | W12: 百万 | X12: 百万 | Y12: 百万 | Z12: 百万 | AA12: 百万 | AB12: 百万 | BG12: 江西省 | CA12: Accumulate | CD12: 2006
A13: @CURRENCY_ENAME | B13: 报表货币单位 | C13: Fundamental Currency | K13: RMB | L13: RMB | M13: RMB | N13: RMB | O13: RMB | P13: RMB | Q13: RMB | R13: RMB | S13: RMB | T13: RMB | U13: RMB | V13: RMB | W13: RMB | X13: RMB | Y13: RMB | Z13: RMB | AA13: RMB | AB13: RMB | BG13: 广西省 | CA13: Hold | CD13: 2007
A14: @DATABEGIN | B14: HK | BG14: 安徽省 | CA14: Reduce | CD14: 2008
B15: 损益表 | C15: Income Statement | BG15: 河北省 | CA15: Sell | CD15: 2009
BG16: 河南省 | CA16: Long-term | CD16: 2010
A17: @HKINDU001 | B17: Revenue | C17: Revenue | K17: =PL!H4 -> 11982.871 | L17: =PL!I4 -> 16379.311 | M17: =PL!J4 -> 21910.66 | N17: =PL!K4 -> 27285.62 | O17: =PL!L4 -> 34439.575 | P17: =PL!M4 -> 38001.876 | Q17: =PL!N4 -> 46207.508 | R17: =PL!O4 -> 50152.524 | ... AB17: =PL!Y4 -> 114194.84 | BG17: 湖北省 | CA17: Short-term | CD17: 2011
A18: @HKINDU002 | B18: Cost of goods sold (-) | C18: Cost of goods sold (-) | K18: =-PL!H19 -> -10667.017 | L18: =-PL!I19 -> -14581.127 | M18: =-PL!J19 -> -19192.443 | N18: =-PL!K19 -> -23539.675 | O18: =-PL!L19 -> -29696.483 | P18: =-PL!M19 -> -32888.761 | Q18: =-PL!N19 -> -40224.63 | R18: =-PL!O19 -> -42537.494 | ... AB18: =-PL!Y19 -> -95642.559 | BG18: 湖南省 | CA18: Not Rated | CD18: 2012
A19: @HKINDU028 | B19: Gross profit | C19: Gross profit | K19: =K17+K18 -> 1315.854 | L19: =L17+L18 -> 1798.184 | M19: =M17+M18 -> 2718.217 | N19: =N17+N18 -> 3745.945 | O19: =O17+O18 -> 4743.092 | P19: =P17+P18 -> 5113.115 | Q19: =Q17+Q18 -> 5982.878 | R19: =R17+R18 -> 7615.03 | ... AB19: =AB17+AB18 -> 18552.281 | BG19: 陕西省 | CD19: 2013
A20: @HKINDU026 | B20: Other gains, net | C20: Other gains, net | K20: =PL!H61+PL!H88 -> 188.889 | L20: =PL!I61+PL!I88 -> 422.315 | M20: =PL!J61+PL!J88 -> 371.09 | N20: =PL!K61+PL!K88 -> 436.542 | O20: =PL!L61+PL!L88 -> 475.339 | P20: =PL!M61+PL!M88 -> 1159.441 | Q20: =PL!N61+PL!N88 -> 1260.12 | R20: =PL!O61+PL!O88 -> 747.678 | ... AB20: =PL!Y61+PL!Y88 -> 281.47053 | BG20: 山西省 | CA20: Consolidated | CB20: A | CC20: RMB | CD20: 2014
A21: @HKINDU008 | B21: Total Operating Expenses (-) | C21: Total Operating Expenses (-) | F21: =F22+F23+F24+F2 -> 0 | K21: =-PL!H79 -> -497.888 | L21: =-PL!I79 -> -577.157 | M21: =-PL!J79 -> -740.074 | N21: =-PL!K79 -> -1042.458 | O21: =-PL!L79 -> -1033.14 | P21: =-PL!M79 -> -1007.396 | Q21: =-PL!N79 -> -1106.084 | R21: =-PL!O79 -> -1394.668 | ... AB21: =-PL!Y79 -> -2460.8988 | BG21: 黑龙江省 | CB21: E | CC21: HKD | CD21: 2016
A22: @HKINDU004 | B22: Selling expenses | C22: Selling expenses | K22: =-PL!H81 -> -4.736 | L22: =-PL!I81 -> -15.523 | M22: =-PL!J81 -> -5.505 | N22: =-PL!K81 -> -82.946 | O22: =-PL!L81 -> -133.871 | P22: =-PL!M81 -> 0 | Q22: =-PL!N81 -> 0 | R22: =-PL!O81 -> 0 | ... AB22: =-PL!Y81 -> 0 | BG22: 辽宁省 | CB22: P | CC22: USD | CD22: 2017
A23: @HKINDU005 | B23: General and administrative expenses | C23: General and administrative expenses | K23: =-PL!H83 -> -466.766 | L23: =-PL!I83 -> -538.68 | M23: =-PL!J83 -> -704.139 | N23: =-PL!K83 -> -959.512 | O23: =-PL!L83 -> -899.269 | P23: =-PL!M83 -> 0 | Q23: =-PL!N83 -> 0 | R23: =-PL!O83 -> 0 | ... AB23: =-PL!Y83 -> 0 | BG23: 吉林省 | CC23: SGD | CD23: 2015
A24: @HKINDU006 | B24: R&D expenses | C24: R&D expenses | BG24: 云南省 | CC24: CAD | CD24: 2018
A25: @HKINDU003 | B25: Other Operating Expenses (-) | C25: Other Operating Expenses (-) | K25: =K21-K22-K23 -> -26.386 | L25: =L21-L22-L23 -> -22.954 | M25: =M21-M22-M23 -> -30.43 | N25: =N21-N22-N23 -> 0 | O25: =O21-O22-O23 -> 0 | P25: =P21-P22-P23 -> -1007.396 | Q25: =Q21-Q22-Q23 -> -1106.084 | R25: =R21-R22-R23 -> -1394.668 | ... AB25: =AB21-AB22-AB23 -> -2460.8988 | BG25: 贵州省 | CD25: 2019
A26: @HKINDU027 | B26: Operating profit | C26: Operating profit | K26: =K19+K21+K20 -> 1006.855 | L26: =L19+L21+L20 -> 1643.342 | M26: =M19+M21+M20 -> 2349.233 | N26: =N19+N21+N20 -> 3140.029 | O26: =O19+O21+O20 -> 4185.291 | P26: =P19+P21+P20 -> 5265.16 | Q26: =Q19+Q21+Q20 -> 6136.914 | R26: =R19+R21+R20 -> 6968.04 | ... AB26: =AB19+AB21+AB20 -> 16372.853 | BG26: 甘肃省 | CD26: 2020
A27: @HKINDU007 | B27: Financial costs (-) | C27: Financial costs (-) | K27: =K28-K29 -> -15.552 | L27: =L28-L29 -> -192.69 | M27: =M28-M29 -> -239.375 | N27: =N28-N29 -> -418.44 | O27: =O28-O29 -> -455.829 | P27: =P28-P29 -> -629.105 | Q27: =Q28-Q29 -> -688.159 | R27: =R28-R29 -> -1069.754 | ... AB27: =AB28-AB29 -> -2740.134 | BG27: 内蒙古
A28: @HKINDU010 | B28: Interest Expense (-) | C28: Interest Expense (-) | K28: =-PL!H90 -> -15.552 | L28: =-PL!I90 -> -192.69 | M28: =-PL!J90 -> -239.375 | N28: =-PL!K90 -> -418.44 | O28: =-PL!L90 -> -455.829 | P28: =-PL!M90 -> -629.105 | Q28: =-PL!N90 -> -688.159 | R28: =-PL!O90 -> -1069.754 | ... AB28: =-PL!Y90 -> -2740.134 | BG28: 宁夏
A29: @HKINDU009 | B29: Interest Income (+) | C29: Interest Income (+) | K29: 0 | L29: 0 | M29: 0 | N29: 0 | O29: 0 | P29: 0 | Q29: 0 | R29: 0 | S29: 0 | T29: 0 | U29: 0 | V29: 0 | W29: 0 | X29: 0 | Y29: 0 | Z29: 0 | AA29: 0 | AB29: 0 | BG29: 西藏
A30: @HKINDU012 | B30: Foreign Exchange Gain/Loss (+/-) | C30: Foreign Exchange Gain/Loss (+/-) | K30: 0 | L30: 0 | M30: 0 | N30: 0 | O30: 0 | P30: 0 | Q30: 0 | R30: 0 | S30: 0 | T30: 0 | U30: 0 | V30: 0 | W30: 0 | X30: 0 | Y30: 0 | Z30: 0 | AA30: 0 | AB30: 0 | BG30: 新疆 | CA30: 合并
A31: @HKINDU014 | B31: Net Participation Income/Associates Profits (+/-) | C31: Net Participation Income/Associates Profits (+/-) | K31: =PL!H100 -> 342.164 | L31: =PL!I100 -> 393.649 | M31: =PL!J100 -> 431.539 | N31: =PL!K100 -> 452.169 | O31: =PL!L100 -> 318.132 | P31: =PL!M100 -> 496.19 | Q31: =PL!N100 -> 562.965 | R31: =PL!O100 -> 891.68 | ... AB31: =PL!Y100 -> 922.1426 | BG31: 青海省
A32: @HKINDU013 | B32: Other Income/ Expense (+/-) | C32: Other Income/ Expense (+/-) | K32: =PL!H100 -> 342.164 | L32: =PL!I100 -> 393.649 | M32: =PL!J100 -> 431.539 | N32: =PL!K100 -> 452.169 | O32: =PL!L100 -> 318.132 | P32: =PL!M100 -> 496.19 | Q32: =PL!N100 -> 562.965 | R32: =PL!O100 -> 891.68 | ... AB32: =PL!Y100 -> 922.1426 | BG32: 香港
A33: @HKINDU017 | B33: Profit before taxes | C33: Profit before taxes | K33: =K26+K28+K31 -> 1333.467 | L33: =L26+L28+L31 -> 1844.301 | M33: =M26+M28+M31 -> 2541.397 | N33: =N26+N28+N31 -> 3173.758 | O33: =O26+O28+O31 -> 4047.594 | P33: =P26+P28+P31 -> 5132.245 | Q33: =Q26+Q28+Q31 -> 6011.72 | R33: =R26+R28+R31 -> 6789.966 | ... AB33: =AB26+AB28+AB31 -> 14554.861 | BG33: 澳门
A34: @HKINDU018 | B34: Taxes on Profit (-) | C34: Taxes on Profit (-) | K34: =-PL!H105 -> -213.218 | L34: =-PL!I105 -> -334.122 | M34: =-PL!J105 -> 404.896 | N34: =-PL!K105 -> -503.071 | O34: =-PL!L105 -> -659.716 | P34: =-PL!M105 -> -659.562 | Q34: =-PL!N105 -> -1004.504 | R34: =-PL!O105 -> -1255.662 | ... AB34: =-PL!Y105 -> -3602.509 | BG34: 台湾
A35: @HKINDU019 | B35: Minority Interests (+/-) | C35: Minority Interests (+/-) | K35: =-PL!H109 -> -83.971 | L35: =-PL!I109 -> -2.774 | M35: =-PL!J109 -> -5.042 | N35: =-PL!K109 -> 78.864 | O35: =-PL!L109 -> 69.532 | P35: =-PL!M109 -> 51.443 | Q35: =-PL!N109 -> 122.85 | R35: =-PL!O109 -> -44.213 | ... AB35: =-PL!Y109 -> -228.79432 | BG35: 国外
A36: @HKINDU020 | B36: Preference Dividends (-) | C36: Preference Dividends (-) | BG36: 其他
A37: @HKINDU022 | B37: Net Profit | C37: Net Profit | K37: =PL!H112 -> 1036.278 | L37: =PL!I112 -> 1507.405 | M37: =PL!J112 -> 2941.251 | N37: =PL!K112 -> 2749.551 | O37: =PL!L112 -> 3457.41 | P37: =PL!M112 -> 4524.126 | Q37: =PL!N112 -> 5130.066 | R37: =PL!O112 -> 5490.091 | ... AB37: =PL!Y112 -> 10494.75
A38: @HKINDU023 | B38: Adjustments (Non Recurrent Items) (+/-) | C38: Adjustments (Non Recurrent Items) (+/-)
A39: @HKINDU024 | B39: Recurrent Net Profit | C39: Recurrent Net Profit | K39: =PL!H118 -> 1036.278 | L39: =PL!I118 -> 1507.405 | M39: =PL!J118 -> 2131.459 | N39: =PL!K118 -> 2749.551 | O39: =PL!L118 -> 3457.41 | P39: =PL!M118 -> 4153 | Q39: =PL!N118 -> 4153.546 | R39: =PL!O118 -> 5072.521 | ... AB39: =PL!Y118 -> 10493.75
A40: @HKINDU021 | B40: Dividends | C40: Dividends | K40: =PL!H129 -> 251.561 | L40: =PL!I129 -> 430.382 | M40: =PL!J129 -> 622.1 | N40: =PL!K129 -> 816.636 | O40: =PL!L129 -> 895.251 | P40: =PL!M129 -> 1338 | Q40: =PL!N129 -> 1481 | R40: =PL!O129 -> 1767.2048 | ... AB40: =PL!Y129 -> 3673.1625
...

Sheet Cover
A1: =TODAY() -> 46120
A2: 8.49 | J2: =14.2/A2-1 -> 0.67255595
A3: 主要财务数据
A4: （百万人民币） | B4: 2005A | C4: 2006A | D4: 2007A | E4: 2008A | F4: 2009A | G4: 2010A | H4: 2011A | I4: 2012A | J4: 2013A | K4: 2014A | L4: 2015A | M4: 2016A | N4: 2017A | O4: 2018A | P4: =PL!Q3 -> 2019A | Q4: =PL!R3 -> 2020A | R4: =PL!S3 -> 2021A | S4: =PL!T3 -> 2022A | T4: =PL!U3 -> 2023A | U4: =PL!V3 -> 2024A | V4: =PL!W3 -> 2025A | W4: =PL!X3 -> 2026E | X4: =PL!Y3 -> 2027E
A5: 主营业务收入 | B5: =PL!C4 -> 7664.252 | C5: =PL!D4 -> 10294.826 | D5: =PL!E4 -> 10168.321 | E5: =PL!F4 -> 11021.405 | F5: =PL!G4 -> 11341.998 | G5: =PL!H4 -> 11982.871 | H5: =PL!I4 -> 16379.311 | I5: =PL!J4 -> 21910.66 | ... X5: =PL!Y4 -> 114194.84
A6: (+/-%) | C6: =(C5/B5-1)*1 -> 0.34322645 | D6: =(D5/C5-1)*1 -> -0.012288212 | E6: =(E5/D5-1)*1 -> 0.08389625 | F6: =(F5/E5-1)*1 -> 0.029088215 | G6: =(G5/F5-1)*1 -> 0.056504418 | H6: =(H5/G5-1)*1 -> 0.36689371 | I6: =(I5/H5-1)*1 -> 0.3377034 | J6: =(J5/I5-1)*1 -> 0.24531256 | ... X6: =(X5/W5-1)*1 -> 0.10268765
A7: 税前利润 | B7: =PL!C103 -> 201.524 | C7: =PL!D103 -> 271.044 | D7: =PL!E103 -> 530.31 | E7: =PL!F103 -> 570.665 | F7: =PL!G103 -> 722.08 | G7: =PL!H103 -> 1333.467 | H7: =PL!I103 -> 1844.301 | I7: =PL!J103 -> 2541.397 | ... X7: =PL!Y103 -> 14554.861
A8: (+/-%) | C8: =(C7/B7-1)*1 -> 0.34497132 | D8: =(D7/C7-1)*1 -> 0.9565458 | E8: =(E7/D7-1)*1 -> 0.076097 | F8: =(F7/E7-1)*1 -> 0.2653308 | G8: =(G7/F7-1)*1 -> 0.84670258 | H8: =(H7/G7-1)*1 -> 0.3830871 | I8: =(I7/H7-1)*1 -> 0.37797301 | J8: =(J7/I7-1)*1 -> 0.24882417 | ... X8: =(X7/W7-1)*1 -> 0.084244145
A9: 净利润 | B9: =PL!C112 -> 152.021 | C9: =PL!D112 -> 222.182 | D9: =PL!E112 -> 404.893 | E9: =PL!F112 -> 489.321 | F9: =PL!G112 -> 612.531 | G9: =PL!H112 -> 1036.278 | H9: =PL!I112 -> 1507.405 | I9: =PL!J112 -> 2941.251 | ... X9: =PL!Y112 -> 10494.75
A10: (+/-%) | C10: =(C9/B9-1)*1 -> 0.46152176 | D10: =(D9/C9-1)*1 -> 0.82234835 | E10: =(E9/D9-1)*1 -> 0.20851929 | F10: =(F9/E9-1)*1 -> 0.2517979 | G10: =(G9/F9-1)*1 -> 0.69179682 | H10: =(H9/G9-1)*1 -> 0.4546338 | I10: =(I9/H9-1)*1 -> 0.95120157 | J10: =(J9/I9-1)*1 -> -0.065176348 | ... X10: =(X9/W9-1)*1 -> 0.086239244
A11: 摊薄每股盈利(HK$) | B11: =PL!C122 -> 0.028779773 | C11: =PL!D122 -> 0.042062265 | D11: =PL!E122 -> 0.076652099 | E11: =PL!F122 -> 0.092635541 | F11: =PL!G122 -> 0.11596098 | G11: =PL!H122 -> 0.19618241 | H11: =PL!I122 -> 0.28537356 | I11: =PL!J122 -> 0.55682134 | ... X11: =PL!Y122 -> 1.9868079
A12: 市盈率 | B12: =PL!C123 -> 0 | C12: =PL!D123 -> 201.84362 | D12: =PL!E123 -> 110.76018 | E12: =PL!F123 -> 91.649489 | F12: =PL!G123 -> 73.214286 | G12: =PL!H123 -> 43.276051 | H12: =PL!I123 -> 29.750478 | I12: =PL!J123 -> 15.24726 | ... X12: =PL!Y123 -> 4.2731861
A13: 市净率 | B13: =PL!C128 -> 0 | C13: =PL!D128 -> 46.033642 | D13: =PL!E128 -> 20.803625 | E13: =PL!F128 -> 17.773069 | F13: =PL!G128 -> 10.417721 | G13: =PL!H128 -> 9.7080864 | H13: =PL!I128 -> 4.7254327 | I13: =PL!J128 -> 3.3195118 | ... X13: =PL!Y128 -> 0.53253311
A14: EV/EBITDA | B14: =PL!C138 -> 0 | C14: =PL!D138 -> 121.95838 | D14: =PL!E138 -> 74.952155 | E14: =PL!F138 -> 62.542272 | F14: =PL!G138 -> 42.3423 | G14: =PL!H138 -> 25.810928 | H14: =PL!I138 -> 16.794395 | I14: =PL!J138 -> 13.019921 | ... X14: =PL!Y138 -> 5.7751923
A15: 净资产收益率(%) | B15: =PL!C140 -> 0 | C15: =PL!D140 -> 0.24659394 | D15: =PL!E140 -> 0.25872716 | E15: =PL!F140 -> 0.20915891 | F15: =PL!G140 -> 0.17941637 | G15: =PL!H140 -> 0.23223914 | H15: =PL!I140 -> 0.21366778 | I15: =PL!J140 -> 0.255759 | ... X15: =PL!Y140 -> 0.13011735
A16: 现金分红收益率(%) | B16: =PL!C132 -> 0 | C16: =PL!D132 -> 0.0042676655 | D16: =PL!E132 -> 0.00501694 | E16: =PL!F132 -> 0.0096297093 | F16: =PL!G132 -> 0.0074385906 | G16: =PL!H132 -> 0.0099448499 | H16: =PL!I132 -> 0.014133382 | I16: =PL!J132 -> 0.018848986 | ... X16: =PL!Y132 -> 0.093265883
A17: 净利润率 | B17: =PL!C139 -> 0 | C17: =PL!D139 -> 0.021581909 | D17: =PL!E139 -> 0.039819062 | E17: =PL!F139 -> 0.044397334 | F17: =PL!G139 -> 0.054005564 | G17: =PL!H139 -> 0.086479943 | H17: =PL!I139 -> 0.092031038 | I17: =PL!J139 -> 0.13423836 | ... X17: =PL!Y139 -> 0.091902139
A18: 总资产回报率 | B18: =PL!C141 -> 0 | C18: =PL!D141 -> 0.041082886 | D18: =PL!E141 -> 0.053222823 | E18: =PL!F141 -> 0.054467865 | F18: =PL!G141 -> 0.046546741 | G18: =PL!H141 -> 0.055476984 | H18: =PL!I141 -> 0.05638712 | I18: =PL!J141 -> 0.079038702 | ... X18: =PL!Y141 -> 0.033413708
A19: 资产负债率 | B19: =BS!C95 -> 0 | C19: =BS!D95 -> 0.81986395 | D19: =BS!E95 -> 0.7166374 | E19: =BS!F95 -> 0.7191283 | F19: =BS!G95 -> 0.67287603 | G19: =BS!H95 -> 0.75248699 | H19: =BS!I95 -> 0.64474526 | I19: =BS!J95 -> 0.62773643 | ... X19: =BS!Y95 -> 0.69872186
A21: (RMB mn) | B21: =B4 -> 2005A | C21: =C4 -> 2006A | D21: =D4 -> 2007A | E21: =E4 -> 2008A | F21: =F4 -> 2009A | G21: =G4 -> 2010A | H21: =H4 -> 2011A | I21: =I4 -> 2012A | ... X21: =X4 -> 2027E
A22: Revenue | B22: =PL!C4 -> 7664.252 | C22: =PL!D4 -> 10294.826 | D22: =PL!E4 -> 10168.321 | E22: =PL!F4 -> 11021.405 | F22: =PL!G4 -> 11341.998 | G22: =PL!H4 -> 11982.871 | H22: =PL!I4 -> 16379.311 | I22: =PL!J4 -> 21910.66 | ... X22: =PL!Y4 -> 114194.84
A23: (+/-%) | C23: =PL!D5 -> 0.34322645 | D23: =PL!E5 -> -0.012288212 | E23: =PL!F5 -> 0.08389625 | F23: =PL!G5 -> 0.029088215 | G23: =PL!H5 -> 0.056504418 | H23: =PL!I5 -> 0.36689371 | I23: =PL!J5 -> 0.3377034 | J23: =PL!K5 -> 0.24531256 | ... X23: =PL!Y5 -> 0.10268765
A24: Profit Before Tax | B24: =B7 -> 201.524 | C24: =C7 -> 271.044 | D24: =D7 -> 530.31 | E24: =E7 -> 570.665 | F24: =F7 -> 722.08 | G24: =G7 -> 1333.467 | H24: =PL!I103 -> 1844.301 | I24: =PL!J103 -> 2541.397 | J24: =PL!K103 -> 3173.758 | K24: =PL!L103 -> 4047.594 | L24: =PL!M103 -> 5132.245 | M24: =PL!N103 -> 6011.72 | N24: =PL!O103 -> 6789.966 | O24: =PL!P103 -> 6205.505 | ... X24: =PL!Y103 -> 14554.861
A25: (+/-%) | C25: =C8 -> 0.34497132 | D25: =D8 -> 0.9565458 | E25: =E8 -> 0.076097 | F25: =F8 -> 0.2653308 | G25: =G8 -> 0.84670258 | H25: =H24/G24-1 -> 0.3830871 | I25: =I24/H24-1 -> 0.37797301 | J25: =J24/I24-1 -> 0.24882417 | K25: =K24/J24-1 -> 0.27533164 | L25: =L24/K24-1 -> 0.26797426 | M25: =M24/L24-1 -> 0.17136263 | N25: =N24/M24-1 -> 0.1294548 | O25: =O24/N24-1 -> -0.086077162 | ... X25: =X24/W24-1 -> 0.084244145
A26: Net Profit | B26: =B9 -> 152.021 | C26: =PL!D112 -> 222.182 | D26: =PL!E112 -> 404.893 | E26: =PL!F112 -> 489.321 | F26: =PL!G112 -> 612.531 | G26: =PL!H112 -> 1036.278 | H26: =PL!I112 -> 1507.405 | I26: =PL!J112 -> 2941.251 | J26: =PL!K112 -> 2749.551 | ... X26: =PL!Y112 -> 10494.75
A27: (+/-%) | C27: =PL!D113 -> 0.46152176 | D27: =PL!E113 -> 0.82234835 | E27: =PL!F113 -> 0.20851929 | F27: =PL!G113 -> 0.2517979 | G27: =PL!H113 -> 0.69179682 | H27: =PL!I113 -> 0.4546338 | I27: =PL!J113 -> 0.95120157 | J27: =PL!K113 -> -0.065176348 | ... X27: =PL!Y113 -> 0.086239244
A28: EPS (HK$ per share) | B28: =B11 -> 0.028779773 | C28: =PL!D122 -> 0.042062265 | D28: =PL!E122 -> 0.076652099 | E28: =PL!F122 -> 0.092635541 | F28: =PL!G122 -> 0.11596098 | G28: =PL!H122 -> 0.19618241 | H28: =PL!I122 -> 0.28537356 | I28: =PL!J122 -> 0.55682134 | J28: =PL!K122 -> 0.52052976 | ... X28: =PL!Y122 -> 1.9868079
A29: P/E (x) | B29: =B12 -> 0 | C29: =PL!D123 -> 201.84362 | D29: =PL!E123 -> 110.76018 | E29: =PL!F123 -> 91.649489 | F29: =PL!G123 -> 73.214286 | G29: =PL!H123 -> 43.276051 | H29: =PL!I123 -> 29.750478 | I29: =PL!J123 -> 15.24726 | J29: =PL!K123 -> 16.310307 | ... X29: =PL!Y123 -> 4.2731861
A30: P/B (x) | B30: =B13 -> 0 | C30: =PL!D128 -> 46.033642 | D30: =PL!E128 -> 20.803625 | E30: =PL!F128 -> 17.773069 | F30: =PL!G128 -> 10.417721 | G30: =PL!H128 -> 9.7080864 | H30: =PL!I128 -> 4.7254327 | I30: =PL!J128 -> 3.3195118 | J30: =PL!K128 -> 2.8145503 | ... X30: =PL!Y128 -> 0.53253311
A31: EV/EBITDA (X) | B31: =B14 -> 0 | C31: =PL!D138 -> 121.95838 | D31: =PL!E138 -> 74.952155 | E31: =PL!F138 -> 62.542272 | F31: =PL!G138 -> 42.3423 | G31: =PL!H138 -> 25.810928 | H31: =PL!I138 -> 16.794395 | I31: =PL!J138 -> 13.019921 | J31: =PL!K138 -> 11.412272 | ... X31: =PL!Y138 -> 5.7751923
A32: ROE (%) | B32: =B15 -> 0 | C32: =PL!D140 -> 0.24659394 | D32: =PL!E140 -> 0.25872716 | E32: =PL!F140 -> 0.20915891 | F32: =PL!G140 -> 0.17941637 | G32: =PL!H140 -> 0.23223914 | H32: =PL!I140 -> 0.21366778 | I32: =PL!J140 -> 0.255759 | J32: =PL!K140 -> 0.1867682 | ... X32: =PL!Y140 -> 0.13011735
A33: Dividend Yield | B33: =B16 -> 0 | C33: =PL!D132 -> 0.0042676655 | D33: =PL!E132 -> 0.00501694 | E33: =PL!F132 -> 0.0096297093 | F33: =PL!G132 -> 0.0074385906 | G33: =PL!H132 -> 0.0099448499 | H33: =PL!I132 -> 0.014133382 | I33: =PL!J132 -> 0.018848986 | J33: =PL!K132 -> 0.024737838 | ... X33: =PL!Y132 -> 0.093265883
A34: Net Profit Margin | C34: =C17 -> 0.021581909 | D34: =D17 -> 0.039819062 | E34: =E17 -> 0.044397334 | F34: =F17 -> 0.054005564 | G34: =G17 -> 0.086479943 | H34: =PL!I139 -> 0.092031038 | I34: =PL!J139 -> 0.13423836 | J34: =PL!K139 -> 0.10076923 | K34: =PL!L139 -> 0.10039061 | L34: =PL!M139 -> 0.11905007 | M34: =PL!N139 -> 0.11102235 | N34: =PL!O139 -> 0.10946789 | O34: =PL!P139 -> 0.080899641 | ... X34: =PL!Y139 -> 0.091902139
A35: ROA (%) | C35: =C18 -> 0.041082886 | D35: =D18 -> 0.053222823 | E35: =E18 -> 0.054467865 | F35: =F18 -> 0.046546741 | G35: =G18 -> 0.055476984 | H35: =PL!I141 -> 0.05638712 | I35: =PL!J141 -> 0.079038702 | J35: =PL!K141 -> 0.052421615 | K35: =PL!L141 -> 0.051929354 | L35: =PL!M141 -> 0.061886082 | M35: =PL!N141 -> 0.059531175 | N35: =PL!O141 -> 0.046322739 | O35: =PL!P141 -> 0.033059645 | ... X35: =PL!Y141 -> 0.033413708
A36: D/A | C36: =C19 -> 0.81986395 | D36: =D19 -> 0.7166374 | E36: =E19 -> 0.7191283 | F36: =F19 -> 0.67287603 | G36: =G19 -> 0.75248699 | H36: =BS!I95 -> 0.64474526 | I36: =BS!J95 -> 0.62773643 | J36: =BS!K95 -> 0.69137934 | K36: =BS!L95 -> 0.69964058 | L36: =BS!M95 -> 0.68148411 | M36: =BS!N95 -> 0.70211217 | N36: =BS!O95 -> 0.67546852 | O36: =BS!P95 -> 0.68353226 | ... X36: =BS!Y95 -> 0.69872186
A37: CPS (HK$/sh) | F37: =CF!G11/BS!$M$89 -> 0.21752175 | G37: =CF!H11/BS!$M$89 -> 0.0077662471 | H37: =CF!I11/BS!$N$89 -> -0.19016543 | I37: =CF!J11/BS!$N$89 -> -0.63227508 | J37: =CF!K11/BS!$N$89 -> -0.58411746 | K37: =CF!L11/BS!$N$89 -> -0.31974038 | L37: =CF!M11/BS!$N$89 -> 0.056415709 | M37: =CF!N11/BS!$N$89 -> 0.54276456 | N37: =CF!O11/BS!$N$89 -> -0.91736221 | O37: =CF!P11/BS!$N$89 -> -0.36435366 | ... X37: =CF!Y11/BS!$N$89 -> 0.46655233
A39: (RMB mn) | B39: =B4 -> 2005A | C39: =C4 -> 2006A | D39: =D4 -> 2007A | E39: =E4 -> 2008A | F39: =F4 -> 2009A | G39: =G4 -> 2010A | H39: =H4 -> 2011A | I39: =I4 -> 2012A | ... X39: =X4 -> 2027E
A40: Revenue | B40: =B5 -> 7664.252 | C40: =C5 -> 10294.826 | D40: =D5 -> 10168.321 | E40: =E5 -> 11021.405 | F40: =F5 -> 11341.998 | G40: =G5 -> 11982.871 | H40: =H5 -> 16379.311 | I40: =I5 -> 21910.66 | ... L40: =L5 -> 38001.876 | M40: =M22 -> 46207.508 | N40: =N22 -> 50152.524 | O40: =O22 -> 55626.304 | P40: =P22 -> 61669.678 | Q40: =Q22 -> 62458.009 | R40: =R22 -> 77309.614 | S40: =S22 -> 101975.26 | T40: =T22 -> 113734.01 | ... X40: =X22 -> 114194.84
A41: (+/-%) | C41: =C6 -> 0.34322645 | D41: =D6 -> -0.012288212 | E41: =E6 -> 0.08389625 | F41: =F6 -> 0.029088215 | G41: =G6 -> 0.056504418 | H41: =H40/G40-1 -> 0.36689371 | I41: =I40/H40-1 -> 0.3377034 | J41: =J40/I40-1 -> 0.24531256 | K41: =K40/J40-1 -> 0.26218774 | L41: =L40/K40-1 -> 0.10343626 | M41: =M40/L40-1 -> 0.21592702 | N41: =N40/M40-1 -> 0.085376082 | O41: =O40/N40-1 -> 0.10914266 | ... X41: =X40/W40-1 -> 0.10268765
A42: Profit Before Tax | B42: =B7 -> 201.524 | C42: =C7 -> 271.044 | D42: =D7 -> 530.31 | E42: =E7 -> 570.665 | F42: =F7 -> 722.08 | G42: =G7 -> 1333.467 | H42: =H24 -> 1844.301 | I42: =I24 -> 2541.397 | J42: =J24 -> 3173.758 | K42: =K24 -> 4047.594 | L42: =L24 -> 5132.245 | M42: =M24 -> 6011.72 | N42: =N24 -> 6789.966 | O42: =O24 -> 6205.505 | ... X42: =X24 -> 14554.861
...

Sheet DCF
A1: Discounted Cash Flow
A2: Rmb mn
A3: Free cashflow forecast | J3: =PL!T3 -> 2022A | K3: =PL!U3 -> 2023A | L3: =PL!V3 -> 2024A | M3: =PL!W3 -> 2025A | N3: =PL!X3 -> 2026E | O3: =PL!Y3 -> 2027E | P3: =PL!Z3 -> 2028E | Q3: =PL!AA3 -> 2029E | ... W3: =PL!AG3 -> 2035E
B4: Net Revenue | J4: =PL!T4 -> 101975.26 | K4: =PL!U4 -> 113734.01 | L4: =PL!V4 -> 105322.67 | M4: =PL!W4 -> 100448.5 | N4: =PL!X4 -> 103560.46 | O4: =PL!Y4 -> 114194.84 | P4: =PL!Z4 -> 122886.67 | Q4: =PL!AA4 -> 134839.16 | ... W4: =PL!AG4 -> 195930.32
C5: YoY | J5: =PL!T5 -> 0.31905024 | K5: =PL!U5 -> 0.11530981 | L5: =PL!V5 -> -0.073956258 | M5: =PL!W5 -> -0.04627846 | N5: =PL!X5 -> 0.03098065 | O5: =PL!Y5 -> 0.10268765 | P5: =PL!Z5 -> 0.076113993 | Q5: =PL!AA5 -> 0.097264352 | ... W5: =PL!AG5 -> 0.050254062
B6: EBIT | J6: =PL!T133 -> 13770.104 | K6: =PL!U133 -> 15307.856 | L6: =PL!V133 -> 14787.551 | M6: =PL!W133 -> 14437.14 | N6: =PL!X133 -> 16024.37 | O6: =PL!Y133 -> 17294.995 | P6: =PL!Z133 -> 18132.901 | Q6: =PL!AA133 -> 19969.489 | ... W6: =PL!AG133 -> 29014.296
C7: YoY | J7: =PL!T133/PL!R133-1 -> 0.26048453 | K7: =PL!U133/PL!S133-1 -> 0.27000526 | L7: =PL!V133/PL!T133-1 -> 0.073888113 | M7: =PL!W133/PL!U133-1 -> -0.056880336 | N7: =PL!X133/PL!V133-1 -> 0.083639235 | O7: =PL!Y133/PL!W133-1 -> 0.19795163 | P7: =PL!Z133/PL!X133-1 -> 0.13158273 | Q7: =PL!AA133/PL!Y133-1 -> 0.15463972 | ... W7: =PL!AG133/PL!AE133-1 -> 0.10402064
C8: EBIT Margin | J8: =PL!T134 -> 0.13503377 | K8: =PL!U134 -> 0.13459347 | L8: =PL!V134 -> 0.14040235 | M8: =PL!W134 -> 0.14372679 | N8: =PL!X134 -> 0.15473445 | O8: =PL!Y134 -> 0.15145164 | P8: =PL!Z134 -> 0.14755792 | Q8: =PL!AA134 -> 0.14809859 | ... W8: =PL!AG134 -> 0.14808477
B9: EBIT*(1 - t) | J9: =J6*(1-PL!T106) -> 10820.003 | K9: =K6*(1-PL!U106) -> 12284.367 | L9: =L6*(1-PL!V106) -> 11516.398 | M9: =M6*(1-PL!W106) -> 10863.768 | N9: =N6*(1-PL!X106) -> 12058.14 | O9: =O6*(1-PL!Y106) -> 13014.269 | P9: =P6*(1-PL!Z106) -> 13644.783 | Q9: =Q6*(1-PL!AA106) -> 15026.792 | ... W9: =W6*(1-PL!AG106) -> 21832.897
B10: + | C10: Depreciation and Amortization | J10: =CAPEX!T43 -> 587.962 | K10: =CAPEX!U43 -> 731.641 | L10: =CAPEX!V43 -> 765.48 | M10: =CAPEX!W43 -> 1002.475 | N10: =CAPEX!X43 -> 949.41469 | O10: =CAPEX!Y43 -> 1004.5909 | P10: =CAPEX!Z43 -> 1059.8073 | Q10: =CAPEX!AA43 -> 1120.0331 | ... W10: =CAPEX!AG43 -> 1540.1001
B11: - | C11: Change in working capital | J11: =-WC!T7 -> -6972.483 | K11: =-WC!U7 -> -5342.665 | L11: =-WC!V7 -> -8369.435 | M11: =-WC!W7 -> -7275.46 | N11: =-WC!X7 -> -6226.549 | O11: =-WC!Y7 -> -6563.018 | P11: =-WC!Z7 -> -5918.9921 | Q11: =-WC!AA7 -> -8408.1448 | ... W11: =-WC!AG7 -> -9212.3905
B12: - | C12: Capex | J12: =-CAPEX!T3 -> -875.5373 | K12: =-CAPEX!U3 -> -1015.6575 | L12: =-CAPEX!V3 -> -968.17594 | M12: =-CAPEX!W3 -> -838.78107 | N12: =-CAPEX!X3 -> -847.74686 | O12: =-CAPEX!Y3 -> -911.68157 | P12: =-CAPEX!Z3 -> -952.20502 | Q12: =-CAPEX!AA3 -> -1016.4418 | ... W12: =-CAPEX!AG3 -> -1232.6982
B13: Free Cash Flows | J13: =SUM(J9:J12) -> 3559.9443 | K13: =SUM(K9:K12) -> 6657.6851 | L13: =SUM(L9:L12) -> 2944.2672 | M13: =SUM(M9:M12) -> 3752.0024 | N13: =SUM(N9:N12) -> 5933.2585 | O13: =SUM(O9:O12) -> 6544.1605 | P13: =SUM(P9:P12) -> 7833.3928 | Q13: =SUM(Q9:Q12) -> 6722.2387 | ... W13: =SUM(W9:W12) -> 12927.908
C14: YoY | K14: =K13/J13-1 -> 0.87016552 | L14: =L13/K13-1 -> -0.55776412 | M14: =M13/L13-1 -> 0.27434167 | N14: =N13/M13-1 -> 0.58135787 | O14: =O13/N13-1 -> 0.1029623 | P14: =P13/O13-1 -> 0.197005 | Q14: =Q13/P13-1 -> -0.14184839 | R14: =R13/Q13-1 -> 0.14852741 | ... W14: =W13/V13-1 -> 0.066799166
A15: DCF Analysis
B16: PV of FCF | J16: =NPV(T24,O13:W13)+N13 -> 57513.925 | R16: Tax rate | T16: 0.15
B17: Terminal value | J17: =W13*(1+T25)/(T24-T25) -> 146477.43 | R17: Debt ratio | T17: 0.3
B18: PV of terminal value | J18: =J17/(1+T24)^9 -> 65416.423 | R18: Beta | T18: 1.4
B19: Enterprise Value | J19: =J16+J18 -> 122930.35 | R19: Risk free rate | T19: 0.042
B20: Net Cash/(Debt), Minority interests | J20: =-BS!X80-BS!X100 -> -60750.495 | R20: Risk permium | T20: 0.05
B21: Equity Value | J21: =J19+J20 -> 62179.853 | R21: Equity cost | T21: =T19+T20*T18 -> 0.112
B22: Equity value per share (HK$) | J22: =J21/BS!$X$89 -> 11.771545 | R22: Debt cost | T22: 0.06
R23: Debt cost (After tax) | T23: =T22*(1-T16) -> 0.051
R24: WACC | T24: =T23*T17+T21*(1-T17) -> 0.0937
R25: Perpetual Growth | T25: 0.005
G28: Equity value per share (HK$)
G29: Perpetual Growth | J29: =K29-0.5% -> -0.015 | K29: =L29-0.5% -> -0.01 | L29: =M29-0.5% -> -0.005 | M29: =N29-0.5% -> 0 | N29: =T25 -> 0.005 | O29: =N29+0.5% -> 0.01 | P29: =O29+0.5% -> 0.015 | Q29: =P29+0.5% -> 0.02 | R29: =Q29+0.5% -> 0.025
G30: WACC | I30: =I31-0.5% -> 0.0787 | J30: =(NPV($I30,$O$13:$W$13)+$N$13+($W$13*(1+J$29)/($I30-J$29))/(1+$I30)^9+$J$20)/BS!$X$88 -> 13.099938 | K30: =(NPV($I30,$O$13:$W$13)+$N$13+($W$13*(1+K$29)/($I30-K$29))/(1+$I30)^9+$J$20)/BS!$X$88 -> 13.903119 | L30: =(NPV($I30,$O$13:$W$13)+$N$13+($W$13*(1+L$29)/($I30-L$29))/(1+$I30)^9+$J$20)/BS!$X$88 -> 14.802259 | M30: =(NPV($I30,$O$13:$W$13)+$N$13+($W$13*(1+M$29)/($I30-M$29))/(1+$I30)^9+$J$20)/BS!$X$88 -> 15.815649 | N30: =(NPV($I30,$O$13:$W$13)+$N$13+($W$13*(1+N$29)/($I30-N$29))/(1+$I30)^9+$J$20)/BS!$X$88 -> 16.96654 | O30: =(NPV($I30,$O$13:$W$13)+$N$13+($W$13*(1+O$29)/($I30-O$29))/(1+$I30)^9+$J$20)/BS!$X$88 -> 18.284956 | P30: =(NPV($I30,$O$13:$W$13)+$N$13+($W$13*(1+P$29)/($I30-P$29))/(1+$I30)^9+$J$20)/BS!$X$88 -> 19.810344 | Q30: =(NPV($I30,$O$13:$W$13)+$N$13+($W$13*(1+Q$29)/($I30-Q$29))/(1+$I30)^9+$J$20)/BS!$X$88 -> 21.595595 | R30: =(NPV($I30,$O$13:$W$13)+$N$13+($W$13*(1+R$29)/($I30-R$29))/(1+$I30)^9+$J$20)/BS!$X$88 -> 23.713294
I31: =I32-0.5% -> 0.0837 | J31: =(NPV($I31,$O$13:$W$13)+$N$13+($W$13*(1+J$29)/($I31-J$29))/(1+$I31)^9+$J$20)/BS!$X$88 -> 11.695309 | K31: =(NPV($I31,$O$13:$W$13)+$N$13+($W$13*(1+K$29)/($I31-K$29))/(1+$I31)^9+$J$20)/BS!$X$88 -> 12.390898 | L31: =(NPV($I31,$O$13:$W$13)+$N$13+($W$13*(1+L$29)/($I31-L$29))/(1+$I31)^9+$J$20)/BS!$X$88 -> 13.164908 | M31: =(NPV($I31,$O$13:$W$13)+$N$13+($W$13*(1+M$29)/($I31-M$29))/(1+$I31)^9+$J$20)/BS!$X$88 -> 14.031391 | N31: =(NPV($I31,$O$13:$W$13)+$N$13+($W$13*(1+N$29)/($I31-N$29))/(1+$I31)^9+$J$20)/BS!$X$88 -> 15.007975 | O31: =(NPV($I31,$O$13:$W$13)+$N$13+($W$13*(1+O$29)/($I31-O$29))/(1+$I31)^9+$J$20)/BS!$X$88 -> 16.117066 | P31: =(NPV($I31,$O$13:$W$13)+$N$13+($W$13*(1+P$29)/($I31-P$29))/(1+$I31)^9+$J$20)/BS!$X$88 -> 17.387597 | Q31: =(NPV($I31,$O$13:$W$13)+$N$13+($W$13*(1+Q$29)/($I31-Q$29))/(1+$I31)^9+$J$20)/BS!$X$88 -> 18.857583 | R31: =(NPV($I31,$O$13:$W$13)+$N$13+($W$13*(1+R$29)/($I31-R$29))/(1+$I31)^9+$J$20)/BS!$X$88 -> 20.577993
I32: =I33-0.5% -> 0.0887 | J32: =(NPV($I32,$O$13:$W$13)+$N$13+($W$13*(1+J$29)/($I32-J$29))/(1+$I32)^9+$J$20)/BS!$X$88 -> 10.432539 | K32: =(NPV($I32,$O$13:$W$13)+$N$13+($W$13*(1+K$29)/($I32-K$29))/(1+$I32)^9+$J$20)/BS!$X$88 -> 11.038326 | L32: =(NPV($I32,$O$13:$W$13)+$N$13+($W$13*(1+L$29)/($I32-L$29))/(1+$I32)^9+$J$20)/BS!$X$88 -> 11.708766 | M32: =(NPV($I32,$O$13:$W$13)+$N$13+($W$13*(1+M$29)/($I32-M$29))/(1+$I32)^9+$J$20)/BS!$X$88 -> 12.45479 | N32: =(NPV($I32,$O$13:$W$13)+$N$13+($W$13*(1+N$29)/($I32-N$29))/(1+$I32)^9+$J$20)/BS!$X$88 -> 13.289945 | O32: =(NPV($I32,$O$13:$W$13)+$N$13+($W$13*(1+O$29)/($I32-O$29))/(1+$I32)^9+$J$20)/BS!$X$88 -> 14.231219 | P32: =(NPV($I32,$O$13:$W$13)+$N$13+($W$13*(1+P$29)/($I32-P$29))/(1+$I32)^9+$J$20)/BS!$X$88 -> 15.30021 | Q32: =(NPV($I32,$O$13:$W$13)+$N$13+($W$13*(1+Q$29)/($I32-Q$29))/(1+$I32)^9+$J$20)/BS!$X$88 -> 16.524804 | R32: =(NPV($I32,$O$13:$W$13)+$N$13+($W$13*(1+R$29)/($I32-R$29))/(1+$I32)^9+$J$20)/BS!$X$88 -> 17.941642
I33: =T24 -> 0.0937 | J33: =(NPV($I33,$O$13:$W$13)+$N$13+($W$13*(1+J$29)/($I33-J$29))/(1+$I33)^9+$J$20)/BS!$X$88 -> 9.2918222 | K33: =(NPV($I33,$O$13:$W$13)+$N$13+($W$13*(1+K$29)/($I33-K$29))/(1+$I33)^9+$J$20)/BS!$X$88 -> 9.8220812 | L33: =(NPV($I33,$O$13:$W$13)+$N$13+($W$13*(1+L$29)/($I33-L$29))/(1+$I33)^9+$J$20)/BS!$X$88 -> 10.406065 | M33: =(NPV($I33,$O$13:$W$13)+$N$13+($W$13*(1+M$29)/($I33-M$29))/(1+$I33)^9+$J$20)/BS!$X$88 -> 11.052373 | N33: =(NPV($I33,$O$13:$W$13)+$N$13+($W$13*(1+N$29)/($I33-N$29))/(1+$I33)^9+$J$20)/BS!$X$88 -> 11.771545 | O33: =(NPV($I33,$O$13:$W$13)+$N$13+($W$13*(1+O$29)/($I33-O$29))/(1+$I33)^9+$J$20)/BS!$X$88 -> 12.576641 | P33: =(NPV($I33,$O$13:$W$13)+$N$13+($W$13*(1+P$29)/($I33-P$29))/(1+$I33)^9+$J$20)/BS!$X$88 -> 13.484035 | Q33: =(NPV($I33,$O$13:$W$13)+$N$13+($W$13*(1+Q$29)/($I33-Q$29))/(1+$I33)^9+$J$20)/BS!$X$88 -> 14.51455 | R33: =(NPV($I33,$O$13:$W$13)+$N$13+($W$13*(1+R$29)/($I33-R$29))/(1+$I33)^9+$J$20)/BS!$X$88 -> 15.695066
I34: =I33+0.5% -> 0.0987 | J34: =(NPV($I34,$O$13:$W$13)+$N$13+($W$13*(1+J$29)/($I34-J$29))/(1+$I34)^9+$J$20)/BS!$X$88 -> 8.2568492 | K34: =(NPV($I34,$O$13:$W$13)+$N$13+($W$13*(1+K$29)/($I34-K$29))/(1+$I34)^9+$J$20)/BS!$X$88 -> 8.7231423 | L34: =(NPV($I34,$O$13:$W$13)+$N$13+($W$13*(1+L$29)/($I34-L$29))/(1+$I34)^9+$J$20)/BS!$X$88 -> 9.2344011 | M34: =(NPV($I34,$O$13:$W$13)+$N$13+($W$13*(1+M$29)/($I34-M$29))/(1+$I34)^9+$J$20)/BS!$X$88 -> 9.7974591 | N34: =(NPV($I34,$O$13:$W$13)+$N$13+($W$13*(1+N$29)/($I34-N$29))/(1+$I34)^9+$J$20)/BS!$X$88 -> 10.420609 | O34: =(NPV($I34,$O$13:$W$13)+$N$13+($W$13*(1+O$29)/($I34-O$29))/(1+$I34)^9+$J$20)/BS!$X$88 -> 11.114012 | P34: =(NPV($I34,$O$13:$W$13)+$N$13+($W$13*(1+P$29)/($I34-P$29))/(1+$I34)^9+$J$20)/BS!$X$88 -> 11.890259 | Q34: =(NPV($I34,$O$13:$W$13)+$N$13+($W$13*(1+Q$29)/($I34-Q$29))/(1+$I34)^9+$J$20)/BS!$X$88 -> 12.76514 | R34: =(NPV($I34,$O$13:$W$13)+$N$13+($W$13*(1+R$29)/($I34-R$29))/(1+$I34)^9+$J$20)/BS!$X$88 -> 13.758729
I35: =I34+0.5% -> 0.1037 | J35: =(NPV($I35,$O$13:$W$13)+$N$13+($W$13*(1+J$29)/($I35-J$29))/(1+$I35)^9+$J$20)/BS!$X$88 -> 7.3140654 | K35: =(NPV($I35,$O$13:$W$13)+$N$13+($W$13*(1+K$29)/($I35-K$29))/(1+$I35)^9+$J$20)/BS!$X$88 -> 7.7258428 | L35: =(NPV($I35,$O$13:$W$13)+$N$13+($W$13*(1+L$29)/($I35-L$29))/(1+$I35)^9+$J$20)/BS!$X$88 -> 8.1755022 | M35: =(NPV($I35,$O$13:$W$13)+$N$13+($W$13*(1+M$29)/($I35-M$29))/(1+$I35)^9+$J$20)/BS!$X$88 -> 8.6685232 | N35: =(NPV($I35,$O$13:$W$13)+$N$13+($W$13*(1+N$29)/($I35-N$29))/(1+$I35)^9+$J$20)/BS!$X$88 -> 9.2114957 | O35: =(NPV($I35,$O$13:$W$13)+$N$13+($W$13*(1+O$29)/($I35-O$29))/(1+$I35)^9+$J$20)/BS!$X$88 -> 9.8124161 | P35: =(NPV($I35,$O$13:$W$13)+$N$13+($W$13*(1+P$29)/($I35-P$29))/(1+$I35)^9+$J$20)/BS!$X$88 -> 10.481084 | Q35: =(NPV($I35,$O$13:$W$13)+$N$13+($W$13*(1+Q$29)/($I35-Q$29))/(1+$I35)^9+$J$20)/BS!$X$88 -> 11.229641 | R35: =(NPV($I35,$O$13:$W$13)+$N$13+($W$13*(1+R$29)/($I35-R$29))/(1+$I35)^9+$J$20)/BS!$X$88 -> 12.073312
I36: =I35+0.5% -> 0.1087 | J36: =(NPV($I36,$O$13:$W$13)+$N$13+($W$13*(1+J$29)/($I36-J$29))/(1+$I36)^9+$J$20)/BS!$X$88 -> 6.4521159 | K36: =(NPV($I36,$O$13:$W$13)+$N$13+($W$13*(1+K$29)/($I36-K$29))/(1+$I36)^9+$J$20)/BS!$X$88 -> 6.8171633 | L36: =(NPV($I36,$O$13:$W$13)+$N$13+($W$13*(1+L$29)/($I36-L$29))/(1+$I36)^9+$J$20)/BS!$X$88 -> 7.2143169 | M36: =(NPV($I36,$O$13:$W$13)+$N$13+($W$13*(1+M$29)/($I36-M$29))/(1+$I36)^9+$J$20)/BS!$X$88 -> 7.6480071 | N36: =(NPV($I36,$O$13:$W$13)+$N$13+($W$13*(1+N$29)/($I36-N$29))/(1+$I36)^9+$J$20)/BS!$X$88 -> 8.123519 | O36: =(NPV($I36,$O$13:$W$13)+$N$13+($W$13*(1+O$29)/($I36-O$29))/(1+$I36)^9+$J$20)/BS!$X$88 -> 8.6472084 | P36: =(NPV($I36,$O$13:$W$13)+$N$13+($W$13*(1+P$29)/($I36-P$29))/(1+$I36)^9+$J$20)/BS!$X$88 -> 9.2267878 | Q36: =(NPV($I36,$O$13:$W$13)+$N$13+($W$13*(1+Q$29)/($I36-Q$29))/(1+$I36)^9+$J$20)/BS!$X$88 -> 9.8717087 | R36: =(NPV($I36,$O$13:$W$13)+$N$13+($W$13*(1+R$29)/($I36-R$29))/(1+$I36)^9+$J$20)/BS!$X$88 -> 10.593681
G39: % change from DCF TP upon WACC/perpetual growth change
G40: Perpetual Growth | J40: =J29 -> -0.015 | K40: =K29 -> -0.01 | L40: =L29 -> -0.005 | M40: =M29 -> 0 | N40: =N29 -> 0.005 | O40: =O29 -> 0.01 | P40: =P29 -> 0.015 | Q40: =Q29 -> 0.02 | R40: =R29 -> 0.025
